Workbook

Sheet Q-values
B1: albae | C1: stellatae | D1: mac-N | E1: mac - all (strongest N) | F1: bicolor_lyrata | G1: muehlenbergii | H1: mac-all (strongest S) | I1: mac-IL | J1: mac-S | K1: species | L1: cohort
A2: MOR0001 | B2: 1e-05 | C2: 1e-05 | D2: 0.078248 | E2: 0.430639 | F2: 0.00595 | G2: 1e-05 | H2: 0.414044 | I2: 0.063144 | J2: 0.007944 | K2: =VLOOKUP(A2,metadata!A:AC,29,) -> macrocarpa_IL | L2: 2021
A3: MOR0004 | B3: 1e-05 | C3: 1e-05 | D3: 0.384837 | E3: 0.276489 | F3: 1e-05 | G3: 1e-05 | H3: 1e-05 | I3: 0.222749 | J3: 0.115875 | K3: =VLOOKUP(A3,metadata!A:AC,29,) -> macrocarpa_IL | L3: 2021
A4: MOR0005 | B4: 1e-05 | C4: 1e-05 | D4: 0.695745 | E4: 0.228602 | F4: 0.003807 | G4: 0.005102 | H4: 1e-05 | I4: 0.066705 | J4: 1e-05 | K4: =VLOOKUP(A4,metadata!A:AC,29,) -> macrocarpa_IL | L4: 2021
A5: MOR0006 | B5: 1e-05 | C5: 1e-05 | D5: 0.419759 | E5: 0.423061 | F5: 0.001282 | G5: 1e-05 | H5: 1e-05 | I5: 0.098695 | J5: 0.057162 | K5: =VLOOKUP(A5,metadata!A:AC,29,) -> macrocarpa_IL | L5: 2021
A6: MOR0007 | B6: 1e-05 | C6: 1e-05 | D6: 0.10549 | E6: 0.377596 | F6: 0.012539 | G6: 1e-05 | H6: 0.396512 | I6: 1e-05 | J6: 0.107822 | K6: =VLOOKUP(A6,metadata!A:AC,29,) -> macrocarpa_IL | L6: 2021
A7: MOR0008 | B7: 1e-05 | C7: 1e-05 | D7: 0.083803 | E7: 0.171017 | F7: 1e-05 | G7: 1e-05 | H7: 0.74512 | I7: 1e-05 | J7: 1e-05 | K7: =VLOOKUP(A7,metadata!A:AC,29,) -> macrocarpa_MN | L7: 2021
A8: MOR0009 | B8: 1e-05 | C8: 1e-05 | D8: 0.055346 | E8: 0.599547 | F8: 0.01429 | G8: 0.00111 | H8: 0.094583 | I8: 0.120922 | J8: 0.114182 | K8: =VLOOKUP(A8,metadata!A:AC,29,) -> macrocarpa_IL | L8: 2021
A9: MOR0012 | B9: 1e-05 | C9: 1e-05 | D9: 0.078719 | E9: 0.291933 | F9: 1e-05 | G9: 1e-05 | H9: 0.607359 | I9: 1e-05 | J9: 0.021938 | K9: =VLOOKUP(A9,metadata!A:AC,29,) -> macrocarpa_IL | L9: 2021
A10: MOR0013 | B10: 1e-05 | C10: 1e-05 | D10: 0.515193 | E10: 0.414983 | F10: 1e-05 | G10: 0.013378 | H10: 0.004525 | I10: 0.05188 | J10: 1e-05 | K10: =VLOOKUP(A10,metadata!A:AC,29,) -> macrocarpa_MN | L10: 2021
A11: MOR0015 | B11: 1e-05 | C11: 1e-05 | D11: 0.095441 | E11: 0.483782 | F11: 1e-05 | G11: 1e-05 | H11: 0.391702 | I11: 0.027763 | J11: 0.001271 | K11: =VLOOKUP(A11,metadata!A:AC,29,) -> macrocarpa_MN | L11: 2021
A12: MOR0016 | B12: 0.003105 | C12: 0.005412 | D12: 0.534258 | E12: 0.407514 | F12: 0.004541 | G12: 1e-05 | H12: 1e-05 | I12: 0.039257 | J12: 0.005892 | K12: =VLOOKUP(A12,metadata!A:AC,29,) -> macrocarpa_MN | L12: 2021
A13: MOR0018 | B13: 1e-05 | C13: 1e-05 | D13: 0.126281 | E13: 0.269351 | F13: 0.003008 | G13: 1e-05 | H13: 0.584526 | I13: 1e-05 | J13: 0.016795 | K13: =VLOOKUP(A13,metadata!A:AC,29,) -> macrocarpa_MN | L13: 2021
... A391: MOR0600 | B391: 1e-05 | C391: 1e-05 | D391: 0.269783 | E391: 0.422253 | F391: 0.01193 | G391: 1e-05 | H391: 0.230431 | I391: 1e-05 | J391: 0.065563 | K391: =VLOOKUP(A391,metadata!A:AC,29,) -> macrocarpa_MN | L391: 2021
A392: MOR0602 | B392: 1e-05 | C392: 1e-05 | D392: 0.278373 | E392: 0.477968 | F392: 1e-05 | G392: 0.001958 | H392: 0.241651 | I392: 1e-05 | J392: 1e-05 | K392: =VLOOKUP(A392,metadata!A:AC,29,) -> macrocarpa_MN | L392: 2023
A393: MOR0604 | B393: 0.002564 | C393: 1e-05 | D393: 0.094066 | E393: 0.275542 | F393: 0.001582 | G393: 0.007316 | H393: 0.529221 | I393: 0.027902 | J393: 0.061798 | K393: =VLOOKUP(A393,metadata!A:AC,29,) -> macrocarpa_IL | L393: 2023
A394: MOR0605 | B394: 1e-05 | C394: 1e-05 | D394: 0.070476 | E394: 0.412337 | F394: 1e-05 | G394: 1e-05 | H394: 0.457059 | I394: 1e-05 | J394: 0.060078 | K394: =VLOOKUP(A394,metadata!A:AC,29,) -> macrocarpa_IL | L394: 2023
A395: MOR0606 | B395: 1e-05 | C395: 1e-05 | D395: 0.790528 | E395: 0.110664 | F395: 0.00149 | G395: 1e-05 | H395: 0.00813 | I395: 0.089148 | J395: 1e-05 | K395: =VLOOKUP(A395,metadata!A:AC,29,) -> macrocarpa_MN | L395: 2023
A396: MOR0607 | B396: 0.003808 | C396: 0.004568 | D396: 1e-05 | E396: 0.082536 | F396: 0.005208 | G396: 1e-05 | H396: 0.569109 | I396: 1e-05 | J396: 0.33474 | K396: =VLOOKUP(A396,metadata!A:AC,29,) -> macrocarpa_OK | L396: 2023
A397: MOR0608 | B397: 1e-05 | C397: 0.000704 | D397: 0.334453 | E397: 0.42393 | F397: 0.001484 | G397: 1e-05 | H397: 0.113045 | I397: 0.079938 | J397: 0.046427 | K397: =VLOOKUP(A397,metadata!A:AC,29,) -> macrocarpa_IL | L397: 2023
A398: MOR0612 | B398: 1e-05 | C398: 0.003045 | D398: 0.644657 | E398: 0.203553 | F398: 1e-05 | G398: 1e-05 | H398: 1e-05 | I398: 0.116376 | J398: 0.032328 | K398: =VLOOKUP(A398,metadata!A:AC,29,) -> macrocarpa_MN | L398: 2023
A399: MOR0614 | B399: 1e-05 | C399: 1e-05 | D399: 0.619361 | E399: 0.050017 | F399: 1e-05 | G399: 0.000955 | H399: 0.004313 | I399: 0.252458 | J399: 0.072865 | K399: =VLOOKUP(A399,metadata!A:AC,29,) -> macrocarpa_IL | L399: 2023
A400: MOR0615 | B400: 1e-05 | C400: 0.000752 | D400: 0.226937 | E400: 0.422347 | F400: 0.002312 | G400: 1e-05 | H400: 0.334128 | I400: 0.007276 | J400: 0.006227 | K400: =VLOOKUP(A400,metadata!A:AC,29,) -> macrocarpa_MN | L400: 2023
A401: MOR0616 | B401: 0.001974 | C401: 1e-05 | D401: 0.557355 | E401: 0.220796 | F401: 0.010431 | G401: 1e-05 | H401: 1e-05 | I401: 0.041993 | J401: 0.16742 | K401: =VLOOKUP(A401,metadata!A:AC,29,) -> macrocarpa_IL | L401: 2023
A402: MOR0617 | B402: 1e-05 | C402: 0.004648 | D402: 0.56822 | E402: 0.3241 | F402: 1e-05 | G402: 1e-05 | H402: 0.01182 | I402: 0.044189 | J402: 0.046993 | K402: =VLOOKUP(A402,metadata!A:AC,29,) -> macrocarpa_IL | L402: 2023
A403: MOR0618 | B403: 0.005622 | C403: 0.008946 | D403: 0.182667 | E403: 0.330723 | F403: 0.002876 | G403: 1e-05 | H403: 0.457146 | I403: 0.012 | J403: 1e-05 | K403: =VLOOKUP(A403,metadata!A:AC,29,) -> macrocarpa_MN | L403: 2023
... A720: MOR1000 | B720: 0.000641 | C720: 0.007071 | D720: 0.504208 | E720: 0.402353 | F720: 1e-05 | G720: 1e-05 | H720: 0.054733 | I720: 0.006524 | J720: 0.02445 | K720: =VLOOKUP(A720,metadata!A:AC,29,) -> macrocarpa_MN | L720: 2023
A721: OAK.MOR.001245 | B721: 0.00727 | C721: 1e-05 | D721: 1e-05 | E721: 1e-05 | F721: 0.007761 | G721: 0.955808 | H721: 1e-05 | I721: 0.029022 | J721: 9.9e-05 | K721: =VLOOKUP(A721,metadata!A:AC,29,) -> muehlenbergii
A722: OAK.MOR.001369 | B722: 1e-05 | C722: 0.99992 | D722: 1e-05 | E722: 1e-05 | F722: 1e-05 | G722: 1e-05 | H722: 1e-05 | I722: 1e-05 | J722: 1e-05 | K722: =VLOOKUP(A722,metadata!A:AC,29,) -> stellata
A723: OAK.MOR.001370 | B723: 0.264272 | C723: 0.018769 | D723: 0.149131 | E723: 1e-05 | F723: 0.000797 | G723: 0.304751 | H723: 0.024284 | I723: 0.237976 | J723: 1e-05 | K723: =VLOOKUP(A723,metadata!A:AC,29,) -> muehlenbergii
A724: OAK.MOR.001372 | B724: 1e-05 | C724: 0.999916 | D724: 1e-05 | E724: 1e-05 | F724: 1e-05 | G724: 1e-05 | H724: 1e-05 | I724: 1.4e-05 | J724: 1e-05 | K724: =VLOOKUP(A724,metadata!A:AC,29,) -> stellata
A725: OAK.MOR.001377 | B725: 1e-05 | C725: 0.99992 | D725: 1e-05 | E725: 1e-05 | F725: 1e-05 | G725: 1e-05 | H725: 1e-05 | I725: 1e-05 | J725: 1e-05 | K725: =VLOOKUP(A725,metadata!A:AC,29,) -> stellata
A726: OAK.MOR.001378 | B726: 1e-05 | C726: 0.99992 | D726: 1e-05 | E726: 1e-05 | F726: 1e-05 | G726: 1e-05 | H726: 1e-05 | I726: 1e-05 | J726: 1e-05 | K726: =VLOOKUP(A726,metadata!A:AC,29,) -> stellata
A727: OAK.MOR.001383 | B727: 1e-05 | C727: 0.020433 | D727: 1e-05 | E727: 1e-05 | F727: 1e-05 | G727: 0.929293 | H727: 1e-05 | I727: 0.049919 | J727: 0.000305 | K727: =VLOOKUP(A727,metadata!A:AC,29,) -> muehlenbergii
A728: OAK.MOR.001465 | B728: 1e-05 | C728: 0.99992 | D728: 1e-05 | E728: 1e-05 | F728: 1e-05 | G728: 1e-05 | H728: 1e-05 | I728: 1e-05 | J728: 1e-05 | K728: =VLOOKUP(A728,metadata!A:AC,29,) -> stellata
A729: OAK.MOR.001468 | B729: 1e-05 | C729: 0.966219 | D729: 1e-05 | E729: 0.033711 | F729: 1e-05 | G729: 1e-05 | H729: 1e-05 | I729: 1e-05 | J729: 1e-05 | K729: =VLOOKUP(A729,metadata!A:AC,29,) -> stellata
A730: SYST.MOR.0006717 | B730: 0.879815 | C730: 0.026475 | D730: 1e-05 | E730: 1e-05 | F730: 0.047751 | G730: 0.006448 | H730: 1e-05 | I730: 0.014628 | J730: 0.024853 | K730: =VLOOKUP(A730,metadata!A:AC,29,) -> michauxii
A731: SYST.MOR.0006718 | B731: 0.906566 | C731: 0.019605 | D731: 1e-05 | E731: 1e-05 | F731: 0.068545 | G731: 0.005233 | H731: 1e-05 | I731: 1e-05 | J731: 1e-05 | K731: =VLOOKUP(A731,metadata!A:AC,29,) -> michauxii
A732: SYST.MOR.0006719 | B732: 0.875475 | C732: 0.045405 | D732: 1e-05 | E732: 0.026361 | F732: 0.032524 | G732: 0.020195 | H732: 1e-05 | I732: 1e-05 | J732: 1e-05 | K732: =VLOOKUP(A732,metadata!A:AC,29,) -> michauxii
A733: SYST.MOR.0006721 | B733: 0.018535 | C733: 1e-05 | D733: 0.107765 | E733: 1e-05 | F733: 0.005435 | G733: 0.00433 | H733: 1e-05 | I733: 0.139613 | J733: 0.724292 | K733: =VLOOKUP(A733,metadata!A:AC,29,) -> macrocarpa | L733: NA
...

Sheet notes
A1: averages | B1: albae | C1: stellatae | D1: mac-N | E1: mac - all (strongest N) | F1: bicolor_lyrata | G1: muehlenbergii | H1: mac-all (strongest S) | I1: mac-IL | J1: mac-S
A2: alba | B2: 0.93343368 | C2: 0.0050939245 | D2: 0.026520415 | E2: 0.014259792 | F2: 0.0026793019 | G2: 0.0018701509 | H2: 0.0072510566 | I2: 0.0048804906 | J2: 0.0040111887
A3: bicolor | B3: 0.01466344 | C3: 0.00069308 | D3: 0.01347068 | E3: 0.03893204 | F3: 0.80320856 | G3: 0.04233384 | H3: 0.00507076 | I3: 0.0161182 | J3: 0.06550944
A4: lyrata | B4: 0.0018113333 | C4: 0.013587867 | D4: 1e-05 | E4: 0.0127628 | F4: 0.91175 | G4: 0.0018470667 | H4: 0.018933667 | I4: 0.0043422 | J4: 0.034955067
A5: mac OK | B5: 0.002195972 | C5: 0.0033055594 | D5: 0.035856706 | E5: 0.12401169 | F5: 0.006177972 | G5: 0.011698895 | H5: 0.17107321 | I5: 0.064853804 | J5: 0.58082623
A6: mac IL | B6: 0.0034040588 | C6: 0.001412917 | D6: 0.34700862 | E6: 0.29121121 | F6: 0.0034411246 | G6: 0.0023821903 | H6: 0.13320457 | I6: 0.13554601 | J6: 0.082389256
A7: mac MN | B7: 0.0016896585 | C7: 0.0016199652 | D7: 0.48377538 | E7: 0.3042359 | F7: 0.0027360105 | G7: 0.0018329582 | H7: 0.12797627 | I7: 0.065464453 | J7: 0.010669348
A8: michauxii | B8: 0.81299758 | C8: 0.040115 | D8: 0.0001515 | E8: 0.010768417 | F8: 0.080748083 | G8: 0.018956417 | H8: 0.00213175 | I8: 0.0053041667 | J8: 0.02882725
A9: montana | B9: 0.573866 | C9: 0.21891014 | D9: 0.0030957143 | E9: 0.043843857 | F9: 0.059447571 | G9: 0.091697286 | H9: 0.0015131429 | I9: 0.0076164286 | J9: 1e-05
A10: muehlenbergii | B10: 0.010118857 | C10: 0.0079752449 | D10: 0.003540449 | E10: 0.017924796 | F10: 0.0011880408 | G10: 0.94444769 | H10: 0.0053978571 | I10: 0.0074339796 | J10: 0.001973
A11: sinuata | B11: 0.05249875 | C11: 0.829021 | D11: 1e-05 | E11: 0.0182605 | F11: 0.0266315 | G11: 0.049433 | H11: 0.018452 | I11: 0.003477 | J11: 0.00221625
A12: stellata | B12: 0.044455074 | C12: 0.89588252 | D12: 1e-05 | E12: 0.015606333 | F12: 0.00028292593 | G12: 0.0018744815 | H12: 0.041868481 | I12: 1.0148148e-05 | J12: 1e-05

Sheet metadata
B1: SPMCODE | C1: Collector_no | D1: MOTHER | E1: Collection_date | F1: Collectors | G1: Type_of_material | H1: Country | I1: State_Province_Region_territory | J1: substate | K1: substateRank | L1: Site | M1: habitat | N1: associates | O1: livingCollectionsNumber | P1: OrigSourceInfo | Q1: latitude.orig | R1: longitude.orig | S1: MOR_Acc_Num | T1: latitude_georef | U1: longitude_georef | V1: state_province_georef | W1: County_georef | X1: Site_georef | Y1: City_georef | Z1: khufuTips | AA1: stateAbb | AB1: motherSite | AC1: Qsp
A2: OAK.MOR.000635 | B2: QUE000134 | C2: IL-MOR-MH092 | D2: NA | E2: 41100 | F2: Ken Potenberg, Gladys Connolly, Joan Dorrell, Kathy Matejka | G2: fresh, frozen leaves | H2: USA | I2: Illinois | J2: DuPage | K2: Co. | L2: The Morton Arboretum (DuPage County, IL, U.S.A.):Quercus L-97/68-99 | M2: Arboretum | N2: NA | O2: 145-75*1 | P2: collected in Tiller County Colorado U.S.A. | Q2: NA | R2: NA | S2: 174463 | T2: 38.861158 | U2: -105.17268 | V2: Colorado | W2: Tiller | X2: NA | Y2: NA | Z2: OAK.MOR.000635 | AA2: NA | AB2: NA | AC2: gambelii
A3: OAK.MOR.000132 | B3: QUE000295 | C3: CA-DAV-MH22 | D3: NA | E3: 41038 | F3: Marlene Hahn | G3: fresh, frozen leaves | H3: USA | I3: California | J3: Yolo | K3: County | L3: UC Davis Arboretum: Shields Oak Grove: Grid #3-D9; Shields Oak Grove Tree #103 | M3: Arboretum | N3: NA | O3: A63.0004, Qualifier 20536 | P3: Hualapai Mountain Park, 1.6 Miles Down from Park Headquarters: Mojave County: Arizona: 5800 ft. D. Cavagnaro 115. 26 Sep 1963. | Q3: 38.529472 | R3: 121.76485 | S3: 174579 | T3: NA | U3: NA | V3: Arizona | W3: Mojave | X3: Hualapai Mountain Park, 1.6 Miles Down from Park Headquarters. | Y3: NA | Z3: OAK.MOR.000132 | AA3: AZ | AB3: NA | AC3: gambelii
A4: OAK.MOR.001369 | B4: QUE001833 | C4: MO-MG319 | D4: NA | E4: 42905 | F4: Mira Garner, Sara Desmond | G4: fresh, frozen | H4: USA | I4: Missouri | J4: Camden | K4: County | L4: Ha Ha Tonka State Park | M4: Oak Savanna | N4: Quercus alba, Q. muehlenbergii, Q. stellata | O4: NA | P4: NA | Q4: 37.97196 | R4: -92.76205 | S4: 185345 | T4: 37.97196 | U4: -92.76205 | V4: Missouri | W4: Camden | X4: Ha Ha Tonka State Park | Y4: NA | Z4: OAK.MOR.001369 | AA4: MO | AB4: NA | AC4: stellata
A5: OAK.MOR.001370 | B5: QUE001835 | C5: MO-MG321 | D5: NA | E5: 42905 | F5: Mira Garner, Sara Desmond | G5: fresh, frozen | H5: USA | I5: Missouri | J5: Camden | K5: County | L5: Ha Ha Tonka State Park | M5: Oak Savanna | N5: Quercus alba, Q. muehlenbergii, Q. stellata | O5: NA | P5: NA | Q5: 37.97259 | R5: -92.762 | S5: 185347 | T5: 37.97259 | U5: -92.762 | V5: Missouri | W5: Camden | X5: Ha Ha Tonka State Park | Y5: NA | Z5: OAK.MOR.001370 | AA5: MO | AB5: NA | AC5: muehlenbergii
A6: OAK.MOR.001372 | B6: QUE001857 | C6: MO-MG277 | D6: NA | E6: 42905 | F6: Mira Garner, Sara Desmond | G6: fresh, frozen | H6: USA | I6: Missouri | J6: Camden | K6: County | L6: Ha Ha Tonka State Park | M6: Oak Savanna | N6: Quercus alba, Q. muehlenbergii, Q. stellata | O6: NA | P6: NA | Q6: 37.97793 | R6: -92.76516 | S6: 185339 | T6: 37.97793 | U6: -92.76516 | V6: Missouri | W6: Camden | X6: Ha Ha Tonka State Park | Y6: NA | Z6: OAK.MOR.001372 | AA6: MO | AB6: NA | AC6: stellata
A7: OAK.MOR.001378 | B7: QUE001877 | C7: OK-MG346 | D7: NA | E7: 42906 | F7: Mira Garner, Sara Desmond | G7: fresh, frozen | H7: USA | I7: Oklahoma | J7: Osage | K7: County | L7: Pawhuska, Tallgrass Prairie Preserve | M7: near research station | N7: NA | O7: NA | P7: NA | Q7: 36.84541 | R7: -96.41918 | S7: 185817 | T7: 36.84541 | U7: -96.41918 | V7: Oklahoma | W7: Osage | X7: Pawhuska, Tallgrass Prairie Preserve | Y7: NA | Z7: OAK.MOR.001378 | AA7: OK | AB7: NA | AC7: stellata
A8: OAK.MOR.001383 | B8: QUE001898 | C8: OK-MG367 | D8: NA | E8: 42907 | F8: Mira Garner, Sara Desmond | G8: fresh, frozen | H8: USA | I8: Oklahoma | J8: Caddo | K8: County | L8: Hinton, Red Rock Canyon State Park | M8: roadside near canyon | N8: NA | O8: NA | P8: NA | Q8: 35.44085 | R8: -98.35471 | S8: 185002 | T8: 35.44085 | U8: -98.35471 | V8: Oklahoma | W8: Caddo | X8: Hinton, Red Rock Canyon State Park | Y8: NA | Z8: OAK.MOR.001383 | AA8: OK | AB8: NA | AC8: muehlenbergii
A9: OAK.MOR.001465 | B9: QUE002229 | C9: KS-MG409 | D9: NA | E9: 42914 | F9: Mira Garner, Craig C. Freeman, Sara Desmond | G9: fresh, frozen | H9: USA | I9: Kansas | J9: Johnson | K9: County | L9: Shawnee Mission Park | M9: Woods area | N9: NA | O9: NA | P9: NA | Q9: 38.97864 | R9: -94.80724 | S9: 184702 | T9: 38.97864 | U9: -94.80724 | V9: Kansas | W9: Johnson | X9: Shawnee Mission Park | Y9: NA | Z9: OAK.MOR.001465 | AA9: KS | AB9: NA | AC9: stellata
A10: SYST.MOR.0006721 | B10: QUE003291 | C10: MO_SH_002_All | D10: NA | E10: 44713 | F10: Alan Whittemore, Andrew Hipp, Brett Fredericksen, Heather McCarthy, Ian Pearse, Jeannine Cavender-Bares, Klara Peterson, Leah Samuels, Mira Garner, Paul Manos | G10: fresh frozen | H10: USA | I10: Missouri | J10: Franklin | K10: County | L10: Shaw Nature Preserve | M10: Bottomland ÃƒÂ¢Ã¢â€šÂ¬Ã¢â‚¬ÂMeramac river floodplain | N10: Populus grandidentata, Asimona triloba, Ulmus rubra, Platanus occidentalis, Fraxinus americana, Celtis occidentalis, Quercus macrocarpa | O10: NA | P10: NA | Q10: 38.461996 | R10: -90.814959 | S10: NA | T10: 38.461996 | U10: -90.814959 | V10: Missouri | W10: Franklin | X10: Shaw Nature Preserve | Y10: NA | Z10: SYST.MOR.0006721 | AA10: MO | AB10: NA | AC10: macrocarpa
A11: SYST.MOR.0006727 | B11: QUE003297 | C11: MO_SH_008_All | D11: NA | E11: 44713 | F11: Alan Whittemore, Andrew Hipp, Brett Fredericksen, Heather McCarthy, Ian Pearse, Jeannine Cavender-Bares, Klara Peterson, Leah Samuels, Mira Garner, Paul Manos | G11: fresh frozen | H11: USA | I11: Missouri | J11: Franklin | K11: County | L11: Shaw Nature Preserve | M11: Bluffs of Meramac River | N11: sugar maple, Quercus muehlenbergii | O11: NA | P11: NA | Q11: 38.461624 | R11: -90.818267 | S11: NA | T11: 38.461624 | U11: -90.818267 | V11: Missouri | W11: Franklin | X11: Shaw Nature Preserve | Y11: NA | Z11: SYST.MOR.0006727 | AA11: MO | AB11: NA | AC11: muehlenbergii
A12: SYST.MOR.0006728 | B12: QUE003298 | C12: MO_SH_009_All | D12: NA | E12: 44713 | F12: Alan Whittemore, Andrew Hipp, Brett Fredericksen, Heather McCarthy, Ian Pearse, Jeannine Cavender-Bares, Klara Peterson, Leah Samuels, Mira Garner, Paul Manos | G12: fresh frozen | H12: USA | I12: Missouri | J12: Franklin | K12: County | L12: Shaw Nature Preserve | M12: Open woodland / savanna / thin soil atop limestone | N12: Quercus stellata, Quercus muehlenbergii, Carya ovata, Quercus rubra, Lonicera sp., Desmodium sp., Cercis sp., Rhus radicans, Rhus arromatica | O12: NA | P12: NA | Q12: 38.462029 | R12: -90.818313 | S12: NA | T12: 38.462029 | U12: -90.818313 | V12: Missouri | W12: Franklin | X12: Shaw Nature Preserve | Y12: NA | Z12: SYST.MOR.0006728 | AA12: MO | AB12: NA | AC12: muehlenbergii
A13: SYST.MOR.0006742 | B13: QUE003299 | C13: MO_SH_010_All | D13: NA | E13: 44713 | F13: Alan Whittemore, Andrew Hipp, Brett Fredericksen, Heather McCarthy, Ian Pearse, Jeannine Cavender-Bares, Klara Peterson, Leah Samuels, Mira Garner, Paul Manos | G13: fresh frozen | H13: USA | I13: Missouri | J13: Franklin | K13: County | L13: Shaw Nature Preserve | M13: Woodland savanna this soil on limestone | N13: Quercus stellata, Quercus muehlenbergii, Fraxinus alba, Carya ovata, Verbesina sp., Cercis sp., Rhus artomatica, Monarda sp. | O13: NA | P13: NA | Q13: 38.46199 | R13: -90.818418 | S13: NA | T13: 38.46199 | U13: -90.818418 | V13: Missouri | W13: Franklin | X13: Shaw Nature Preserve | Y13: NA | Z13: SYST.MOR.0006742 | AA13: MO | AB13: NA | AC13: stellata
A14: SYST.MOR.0006743 | B14: QUE003300 | C14: MO_SH_011_All | D14: NA | E14: 44713 | F14: Alan Whittemore, Andrew Hipp, Brett Fredericksen, Heather McCarthy, Ian Pearse, Jeannine Cavender-Bares, Klara Peterson, Leah Samuels, Mira Garner, Paul Manos | G14: fresh frozen | H14: USA | I14: Missouri | J14: Franklin | K14: County | L14: Shaw Nature Preserve | M14: Bluffs above Mermac River | N14: Acer saccharum, shagbark hickory, Carya ovata, Ulmas rubra | O14: NA | P14: NA | Q14: 38.462391 | R14: -90.817857 | S14: NA | T14: 38.462391 | U14: -90.817857 | V14: Missouri | W14: Franklin | X14: Shaw Nature Preserve | Y14: NA | Z14: SYST.MOR.0006743 | AA14: MO | AB14: NA | AC14: alba
A15: SYST.MOR.0006744 | B15: QUE003301 | C15: MO_SH_012_All | D15: NA | E15: 44713 | F15: Alan Whittemore, Andrew Hipp, Brett Fredericksen, Heather McCarthy, Ian Pearse, Jeannine Cavender-Bares, Klara Peterson, Leah Samuels, Mira Garner, Paul Manos | G15: fresh frozen | H15: USA | I15: Missouri | J15: Franklin | K15: County | L15: Shaw Nature Preserve | M15: Sloped woodlands | N15: Carya ovata, Acer saccharum, Quercus rubra, Quercus muehlenbergii, Asarum canadense, Podophyllum sp., Parthenocissus sp. | O15: NA | P15: NA | Q15: 38.46295 | R15: -90.817616 | S15: NA | T15: 38.46295 | U15: -90.817616 | V15: Missouri | W15: Franklin | X15: Shaw Nature Preserve | Y15: NA | Z15: SYST.MOR.0006744 | AA15: MO | AB15: NA | AC15: muehlenbergii
A16: SYST.MOR.0006747 | B16: QUE003304 | C16: MO_SH_015_All | D16: NA | E16: 44713 | F16: Alan Whittemore, Andrew Hipp, Brett Fredericksen, Heather McCarthy, Ian Pearse, Jeannine Cavender-Bares, Klara Peterson, Leah Samuels, Mira Garner, Paul Manos | G16: fresh frozen | H16: USA | I16: Missouri | J16: Franklin | K16: County | L16: Shaw Nature Preserve | M16: Woodlands above Mermac River Floodlplains | N16: Red oak, Sugar maple, Fraxinus sp. | O16: NA | P16: NA | Q16: 38.462662 | R16: -90.818129 | S16: NA | T16: 38.462662 | U16: -90.818129 | V16: Missouri | W16: Franklin | X16: Shaw Nature Preserve | Y16: NA | Z16: SYST.MOR.0006747 | AA16: MO | AB16: NA | AC16: stellata
A17: SYST.MOR.0006748 | B17: QUE003305 | C17: MO_SH_016_All | D17: NA | E17: 44713 | F17: Alan Whittemore, Andrew Hipp, Brett Fredericksen, Heather McCarthy, Ian Pearse, Jeannine Cavender-Bares, Klara Peterson, Leah Samuels, Mira Garner, Paul Manos | G17: fresh frozen | H17: USA | I17: Missouri | J17: Franklin | K17: County | L17: Shaw Nature Preserve | M17: Top of hill ÃƒÂ¢Ã¢â€šÂ¬Ã¢â‚¬Â open woodland ; thin gravely soil on limestone | N17: Quercus stellata, Fraxinus sp., Cercis canadense | O17: NA | P17: NA | Q17: 38.462483 | R17: -90.818432 | S17: NA | T17: 38.462483 | U17: -90.818432 | V17: Missouri | W17: Franklin | X17: Shaw Nature Preserve | Y17: NA | Z17: SYST.MOR.0006748 | AA17: MO | AB17: NA | AC17: stellata
A18: SYST.MOR.0006753 | B18: QUE003310 | C18: IL_OB_021_All | D18: NA | E18: 44714 | F18: Alan Whittemore, Andrew Hipp, Brett Fredericksen, Heather McCarthy, Jeannine Cavender-Bares, Klara Peterson, Leah Samuels, Mira Garner, Paul Manos | G18: fresh frozen | H18: USA | I18: Illinois | J18: Jackson | K18: County | L18: Oakwood Bottoms, Shawnee National Forest | M18: Bottomland forest, floodplain | N18: Acer saccharinum, sweetgum, pin oak, Ulmus sp., hackberry | O18: NA | P18: NA | Q18: NA | R18: NA | S18: NA | T18: NA | U18: NA | V18: Illinois | W18: Jackson | X18: Oakwood Bottoms, Shawnee National Forest | Y18: NA | Z18: SYST.MOR.0006753 | AA18: IL | AB18: NA | AC18: macrocarpa
A19: SYST.MOR.0006756 | B19: QUE003312 | C19: IL_OB_024_All | D19: NA | E19: 44714 | F19: Alan Whittemore, Andrew Hipp, Brett Fredericksen, Heather McCarthy, Jeannine Cavender-Bares, Klara Peterson, Leah Samuels, Mira Garner, Paul Manos | G19: fresh frozen | H19: USA | I19: Illinois | J19: Jackson | K19: County | L19: Oakwood Bottoms, Shawnee National Forest | M19: Bottomland-flats | N19: Quercus macrocarpa, Quercus palustris, Liquidambar styraciflua | O19: NA | P19: NA | Q19: NA | R19: NA | S19: NA | T19: NA | U19: NA | V19: Illinois | W19: Jackson | X19: Oakwood Bottoms, Shawnee National Forest | Y19: NA | Z19: SYST.MOR.0006756 | AA19: IL | AB19: NA | AC19: lyrata
A20: SYST.MOR.0006762 | B20: QUE003318 | C20: IL_OB_030_All | D20: NA | E20: 44714 | F20: Alan Whittemore, Andrew Hipp, Brett Fredericksen, Heather McCarthy, Jeannine Cavender-Bares, Klara Peterson, Leah Samuels, Mira Garner, Paul Manos | G20: fresh frozen | H20: USA | I20: Illinois | J20: Jackson | K20: County | L20: Oakwood Bottoms, Shawnee National Forest | M20: Forest bottomlands, floodplains | N20: pin oak, Ulmus americana, Celtis laevigata | O20: NA | P20: NA | Q20: NA | R20: NA | S20: NA | T20: NA | U20: NA | V20: Illinois | W20: Jackson | X20: Oakwood Bottoms, Shawnee National Forest | Y20: NA | Z20: SYST.MOR.0006762 | AA20: IL | AB20: NA | AC20: lyrata
A21: SYST.MOR.0006764 | B21: QUE003320 | C21: MO_BOT_032_MG | D21: NA | E21: 44715 | F21: Alan Whittemore, Andrew Hipp, Brett Fredericksen, Heather McCarthy, Klara Peterson, Leah Samuels, Mira Garner, Paul Manos | G21: fresh frozen | H21: USA | I21: Missouri | J21: Mississipi | K21: County | L21: Big Oak Tree State Park | M21: Dense bottomland floodplain mixed deciduous forest | N21: Quercus macrocarpa, Celtis laevigata, pawpaw | O21: NA | P21: NA | Q21: 36.643929 | R21: -89.290992 | S21: NA | T21: 36.643929 | U21: -89.290992 | V21: Missouri | W21: Mississipi | X21: Big Oak Tree State Park | Y21: NA | Z21: SYST.MOR.0006764 | AA21: MO | AB21: NA | AC21: macrocarpa
A22: SYST.MOR.0006771 | B22: QUE003326 | C22: MO_BOT_039_All | D22: NA | E22: 44715 | F22: Alan Whittemore, Andrew Hipp, Brett Fredericksen, Heather McCarthy, Klara Peterson, Leah Samuels, Mira Garner, Paul Manos | G22: fresh frozen | H22: USA | I22: Missouri | J22: Mississipi | K22: County | L22: Big Oak Tree State Park | M22: Dry forest area | N22: Acer nagundo | O22: NA | P22: NA | Q22: NA | R22: NA | S22: NA | T22: NA | U22: NA | V22: Missouri | W22: Mississipi | X22: Big Oak Tree State Park | Y22: NA | Z22: SYST.MOR.0006771 | AA22: MO | AB22: NA | AC22: michauxii
A23: SYST.MOR.0006776 | B23: QUE003331 | C23: MO_BOT_044_All | D23: NA | E23: 44715 | F23: Alan Whittemore, Andrew Hipp, Brett Fredericksen, Heather McCarthy, Klara Peterson, Leah Samuels, Mira Garner, Paul Manos | G23: fresh frozen | H23: USA | I23: Missouri | J23: Mississipi | K23: County | L23: Big Oak Tree State Park | M23: Forest, dry, a bit open | N23: Celtis laevigata, elm | O23: NA | P23: NA | Q23: NA | R23: NA | S23: NA | T23: NA | U23: NA | V23: Missouri | W23: Mississipi | X23: Big Oak Tree State Park | Y23: NA | Z23: SYST.MOR.0006776 | AA23: MO | AB23: NA | AC23: lyrata
A24: SYST.MOR.0006777 | B24: QUE003332 | C24: MO_BOT_045_All | D24: NA | E24: 44715 | F24: Alan Whittemore, Andrew Hipp, Brett Fredericksen, Heather McCarthy, Klara Peterson, Leah Samuels, Mira Garner, Paul Manos | G24: fresh frozen | H24: USA | I24: Missouri | J24: Mississipi | K24: County | L24: Big Oak Tree State Park | M24: Near water, shrubby area | N24: Ulmus rubra, Celtis laevigata, Taxodium distichum | O24: NA | P24: NA | Q24: NA | R24: NA | S24: NA | T24: NA | U24: NA | V24: Missouri | W24: Mississipi | X24: Big Oak Tree State Park | Y24: NA | Z24: SYST.MOR.0006777 | AA24: MO | AB24: NA | AC24: bicolor
A25: SYST.MOR.0006755 | B25: QUE003523 | C25: IL_OB_023_All | D25: NA | E25: 44714 | F25: Alan Whittemore, Andrew Hipp, Brett Fredericksen, Heather McCarthy, Jeannine Cavender-Bares, Klara Peterson, Leah Samuels, Mira Garner, Paul Manos | G25: fresh frozen | H25: USA | I25: Illinois | J25: Jackson | K25: County | L25: Oakwood Bottoms, Shawnee National Forest | M25: Bottomlands forest, floodplains | N25: Black oak, American elm, hackberry | O25: NA | P25: NA | Q25: 37.676004 | R25: -89.412965 | S25: NA | T25: NA | U25: NA | V25: Illinois | W25: Jackson | X25: Oakwood Bottoms, Shawnee National Forest | Y25: NA | Z25: SYST.MOR.0006755 | AA25: IL | AB25: NA | AC25: macrocarpa
A26: SYST.MOR.0006729 | B26: QUE003528 | C26: IL_MOR_135_MG | D26: NA | E26: 44705 | F26: Mira Garner, Keion Mackay, Andrew Hipp | G26: fresh, frozen | H26: USA | I26: Illinois | J26: DuPage | K26: County | L26: The Morton Arboretum | M26: Oak savanna | N26: Quercus ellipsoidalis, Quercus macrocarpa, Clover, bottlebrush grass | O26: NA | P26: NA | Q26: 41.81383 | R26: -88.062933 | S26: NA | T26: 41.81383 | U26: -88.062933 | V26: Illinois | W26: DuPage | X26: The Morton Arboretum | Y26: NA | Z26: SYST.MOR.0006729 | AA26: IL | AB26: NA | AC26: macrocarpa
A27: SYST.MOR.0006781 | B27: QUE003544 | C27: IA_BSP_049_MG | D27: NA | E27: 44720 | F27: Mira Garner, Leah Samuels, Klara Peterson, Briana Beatty | G27: fresh, frozen | H27: USA | I27: Iowa | J27: Story | K27: County | L27: Brookside Park | M27: Wooded area, hillside, near park | N27: Celtis occidentalis, Tilia americana | O27: NA | P27: NA | Q27: 42.029397 | R27: -93.628202 | S27: NA | T27: 42.029397 | U27: -93.628202 | V27: Iowa | W27: Story | X27: Brookside Park | Y27: NA | Z27: SYST.MOR.0006781 | AA27: IA | AB27: NA | AC27: macrocarpa
A28: SYST.MOR.0006785 | B28: QUE003548 | C28: IA_LNW_053_MG | D28: NA | E28: 44721 | F28: Mira Garner, Leah Samuels, Klara Peterson, Briana Beatty | G28: fresh, frozen | H28: USA | I28: Iowa | J28: Van Buren | K28: County | L28: Lindsay Wilderness | M28: Wooded area, bushy foliage | N28: Ironwood | O28: NA | P28: NA | Q28: 40.710201 | R28: -91.794682 | S28: NA | T28: 40.710201 | U28: -91.794682 | V28: Iowa | W28: Van Buren | X28: Lindsay Wilderness | Y28: NA | Z28: SYST.MOR.0006785 | AA28: IA | AB28: NA | AC28: alba
A29: SYST.MOR.0006787 | B29: QUE003550 | C29: IA_LNW_055_MG | D29: NA | E29: 44721 | F29: Mira Garner, Leah Samuels, Klara Peterson, Briana Beatty | G29: fresh, frozen | H29: USA | I29: Iowa | J29: Van Buren | K29: County | L29: Lindsay Wilderness | M29: Lower land, dry forest. Dense brush | N29: Red oak, Acer sp., hickory, Hog-peanut, Yellow violet, Virginia creeper | O29: NA | P29: NA | Q29: 40.708616 | R29: -91.787231 | S29: NA | T29: 40.708616 | U29: -91.787231 | V29: Iowa | W29: Van Buren | X29: Lindsay Wilderness | Y29: NA | Z29: SYST.MOR.0006787 | AA29: IA | AB29: NA | AC29: muehlenbergii
A30: SYST.MOR.0006788 | B30: QUE003551 | C30: IA_LNW_056_MG | D30: NA | E30: 44721 | F30: Mira Garner, Leah Samuels, Klara Peterson, Briana Beatty | G30: fresh, frozen | H30: USA | I30: Iowa | J30: Van Buren | K30: County | L30: Lindsay Wilderness | M30: Forested area, lots of underbrush | N30: American elm, black maple, ironwood, Rubus sp., Jack in the pulpit, Mustard, Gooseberry | O30: NA | P30: NA | Q30: 40.707865 | R30: -91.788325 | S30: NA | T30: 40.707865 | U30: -91.788325 | V30: Iowa | W30: Van Buren | X30: Lindsay Wilderness | Y30: NA | Z30: SYST.MOR.0006788 | AA30: IA | AB30: NA | AC30: muehlenbergii
A31: SYST.MOR.0006791 | B31: QUE003554 | C31: IA_LNW_059_MG | D31: NA | E31: 44721 | F31: Mira Garner, Leah Samuels, Klara Peterson, Briana Beatty | G31: fresh, frozen | H31: USA | I31: Iowa | J31: Van Buren | K31: County | L31: Lindsay Wilderness | M31: Forest, low underbrush, more open, dry | N31: Quercus alba, Quercus macrocarpa, red maple, shagbark hickory, Mayapple, Poison ivy, Ash, Virginia creeper | O31: NA | P31: NA | Q31: 40.707564 | R31: -91.792402 | S31: NA | T31: 40.707564 | U31: -91.792402 | V31: Iowa | W31: Van Buren | X31: Lindsay Wilderness | Y31: NA | Z31: SYST.MOR.0006791 | AA31: IA | AB31: NA | AC31: macrocarpa
A32: SYST.MOR.0006795 | B32: QUE003558 | C32: IA_LNW_063_MG | D32: NA | E32: 44721 | F32: Mira Garner, Leah Samuels, Klara Peterson, Briana Beatty | G32: fresh, frozen | H32: USA | I32: Iowa | J32: Van Buren | K32: County | L32: Lindsay Wilderness | M32: Woodland, bluff hills | N32: red maple, ironwood, Quercus bicolor, hickory, Barberry, Virginia creeper, Chokeberry | O32: NA | P32: NA | Q32: 40.704425 | R32: -91.796592 | S32: NA | T32: 40.704425 | U32: -91.796592 | V32: Iowa | W32: Van Buren | X32: Lindsay Wilderness | Y32: NA | Z32: SYST.MOR.0006795 | AA32: IA | AB32: NA | AC32: bicolor
A33: SYST.MOR.0006796 | B33: QUE003559 | C33: IA_LNW_064_MG | D33: NA | E33: 44721 | F33: Mira Garner, Leah Samuels, Klara Peterson, Briana Beatty | G33: fresh, frozen | H33: USA | I33: Iowa | J33: Van Buren | K33: County | L33: Lindsay Wilderness | M33: Woodland, bluff hills | N33: ash, Rose sp., Chokeberry, Virginia creeper | O33: NA | P33: NA | Q33: 40.703988 | R33: -91.796584 | S33: NA | T33: 40.703988 | U33: -91.796584 | V33: Iowa | W33: Van Buren | X33: Lindsay Wilderness | Y33: NA | Z33: SYST.MOR.0006796 | AA33: IA | AB33: NA | AC33: bicolor
A34: SYST.MOR.0006798 | B34: QUE003561 | C34: IA_CHP_066_MG | D34: NA | E34: 44721 | F34: Mira Garner, Leah Samuels, Klara Peterson, Briana Beatty | G34: fresh, frozen | H34: USA | I34: Iowa | J34: Linn | K34: County | L34: Cherokee Park | M34: Park area | N34: Grass, dandelion | O34: NA | P34: NA | Q34: 41.974717 | R34: -91.721693 | S34: NA | T34: NA | U34: NA | V34: Iowa | W34: Linn | X34: Cherokee Park | Y34: NA | Z34: SYST.MOR.0006798 | AA34: IA | AB34: NA | AC34: macrocarpa
A35: SYST.MOR.0006808 | B35: QUE003571 | C35: MO_TRC_076_MG | D35: NA | E35: 44733 | F35: Leah Samuels, Mira Garner, Erin O'Connell | G35: fresh, frozen | H35: USA | I35: Missouri | J35: St. Louis | K35: County | L35: Tyson Research Center | M35: On side of hill, low foliage, wooded | N35: red cedar, red oak, black oak, Quercus stellata, Redbud, Virginia creeper, American hog peanut, raspberry, buckthorn, flowering dogwood, ash, fragrant sumac | O35: NA | P35: NA | Q35: 38.512384 | R35: -90.575894 | S35: NA | T35: 38.512384 | U35: -90.575894 | V35: Missouri | W35: St. Louis | X35: Tyson Research Center | Y35: NA | Z35: SYST.MOR.0006808 | AA35: MO | AB35: NA | AC35: alba
A36: SYST.MOR.0006830 | B36: QUE003593 | C36: MO_HHT_098_MG | D36: NA | E36: 44734 | F36: Leah Samuels, Mira Garner | G36: fresh, frozen | H36: USA | I36: Missouri | J36: Camden | K36: County | L36: Ha Ha Tonka State Park | M36: Hillside, open grassy area near wooded area | N36: American persimmon, Fragrant sumac, sunflower, dogwood, redbud | O36: NA | P36: NA | Q36: 37.980058 | R36: -92.772782 | S36: NA | T36: 37.980058 | U36: -92.772782 | V36: Missouri | W36: Camden | X36: Ha Ha Tonka State Park | Y36: NA | Z36: SYST.MOR.0006830 | AA36: MO | AB36: NA | AC36: muehlenbergii
A37: SYST.MOR.0006834 | B37: QUE003597 | C37: MO_PSP_MG922_MG | D37: NA | E37: 44735 | F37: Leah Samuels, Mira Garner, Andrew Braun | G37: fresh, frozen | H37: USA | I37: Missouri | J37: Barton | K37: County | L37: Prairie State Park | M37: Wooded area of prairie, riparian? | N37: Hedge apple, Honey locust, Red mulberry, Pin oak, Buckbrush | O37: NA | P37: NA | Q37: 37.531756 | R37: -94.574784 | S37: NA | T37: 37.531756 | U37: -94.574784 | V37: Missouri | W37: Barton | X37: Prairie State Park | Y37: NA | Z37: SYST.MOR.0006834 | AA37: MO | AB37: NA | AC37: muehlenbergii
A38: SYST.MOR.0006846 | B38: QUE003609 | C38: OK_RRC_111_MG | D38: NA | E38: 44736 | F38: Leah Samuels, Mira Garner | G38: fresh, frozen | H38: USA | I38: Oklahoma | J38: Caddo | K38: County | L38: Red Rock Canyon Adventure Park | M38: Dry ridge, little foliage, small trees, rocky dry soils | N38: Quercus marilandica, eastern red cedar, Grasses, California mugwort, Indian blanket | O38: NA | P38: NA | Q38: 35.435951 | R38: -98.353643 | S38: NA | T38: 35.435951 | U38: -98.353643 | V38: Oklahoma | W38: Caddo | X38: Red Rock Canyon Adventure Park | Y38: NA | Z38: SYST.MOR.0006846 | AA38: OK | AB38: NA | AC38: stellata
A39: SYST.MOR.0006849 | B39: QUE003612 | C39: OK_RRC_114_MG | D39: NA | E39: 44736 | F39: Leah Samuels, Mira Garner | G39: fresh, frozen | H39: USA | I39: Oklahoma | J39: Caddo | K39: County | L39: Red Rock Canyon Adventure Park | M39: Dry, open, some trees, little foliage, sandy and rocky | N39: eastern red cedar, Gum bumelia, grasses, Lespedeza sp., Plains fleabane, Indian blanket, hackberry | O39: NA | P39: NA | Q39: 35.436538 | R39: -98.353515 | S39: NA | T39: 35.436538 | U39: -98.353515 | V39: Oklahoma | W39: Caddo | X39: Red Rock Canyon Adventure Park | Y39: NA | Z39: SYST.MOR.0006849 | AA39: OK | AB39: NA | AC39: muehlenbergii
A40: SYST.MOR.0006870 | B40: QUE003633 | C40: TN_BCP_148_MG | D40: NA | E40: 44753 | F40: Leah Samuels, Mira Garner, Andrew Hipp | G40: fresh, frozen | H40: USA | I40: Tennessee | J40: Sumner | K40: County | L40: Bledsoe Creek State Park | M40: Lowlands, forest area near creek, low/thin foliage | N40: Juniper sp., Ulmus rubra, Ulmus olata, Fraxinus sp., Acer nugundo, Elymus sp., Ostrya virginiana, Black locust, Baptisia sp. | O40: NA | P40: NA | Q40: 36.375797 | R40: -86.357923 | S40: NA | T40: 36.375797 | U40: -86.357923 | V40: Tennessee | W40: Sumner | X40: Bledsoe Creek State Park | Y40: NA | Z40: SYST.MOR.0006870 | AA40: TN | AB40: NA | AC40: macrocarpa
...
