Workbook

Sheet TableS4
A1: Specimen Code | B1: Species Determination | C1: Parent Species | D1: Pure | E1: F1 | F1: F2 | G1: Bx1 | H1: Bx2 | I1: Bx3 | J1: Hybrid Class | K1: state | L1: site | M1: lat | N1: lon
A2: QUE001334 | B2: Q. macrocarpa | C2: Q. macrocarpa | D2: 0.9985 | E2: 0 | F2: 0 | G2: 0 | H2: 0 | I2: 0.0015 | J2: Unadmixed | K2: =VLOOKUP(A2,metadata!A:I,9,FALSE) -> IL | L2: =VLOOKUP(A2,metadata!A:F,6,FALSE) -> GalesburgIL | M2: =VLOOKUP(A2,metadata!A:D,4,FALSE) -> 40.990945 | N2: =VLOOKUP(A2,metadata!A:E,5,FALSE) -> -90.402384
A3: QUE001337 | B3: Q. macrocarpa | C3: Q. macrocarpa | D3: 0.99831 | E3: 0 | F3: 0 | G3: 0 | H3: 1e-05 | I3: 0.00168 | J3: Unadmixed | K3: =VLOOKUP(A3,metadata!A:I,9,FALSE) -> IL | L3: =VLOOKUP(A3,metadata!A:F,6,FALSE) -> GalesburgIL | M3: =VLOOKUP(A3,metadata!A:D,4,FALSE) -> 40.990457 | N3: =VLOOKUP(A3,metadata!A:E,5,FALSE) -> -90.405752
A4: QUE001338 | B4: Q. macrocarpa | C4: Q. macrocarpa | D4: 0.99678 | E4: 0 | F4: 0 | G4: 0 | H4: 0 | I4: 0.00322 | J4: Unadmixed | K4: =VLOOKUP(A4,metadata!A:I,9,FALSE) -> IL | L4: =VLOOKUP(A4,metadata!A:F,6,FALSE) -> GalesburgIL | M4: =VLOOKUP(A4,metadata!A:D,4,FALSE) -> 40.990457 | N4: =VLOOKUP(A4,metadata!A:E,5,FALSE) -> -90.405752
A5: QUE001339 | B5: Q. macrocarpa | C5: Q. macrocarpa | D5: 0.99979 | E5: 0 | F5: 0 | G5: 0 | H5: 0 | I5: 0.00021 | J5: Unadmixed | K5: =VLOOKUP(A5,metadata!A:I,9,FALSE) -> IL | L5: =VLOOKUP(A5,metadata!A:F,6,FALSE) -> GalesburgIL | M5: =VLOOKUP(A5,metadata!A:D,4,FALSE) -> 40.990457 | N5: =VLOOKUP(A5,metadata!A:E,5,FALSE) -> -90.405752
A6: QUE001342 | B6: Q. macrocarpa | C6: Q. macrocarpa | D6: 0.99521 | E6: 0 | F6: 0 | G6: 0 | H6: 0 | I6: 0.00478 | J6: Unadmixed | K6: =VLOOKUP(A6,metadata!A:I,9,FALSE) -> IL | L6: =VLOOKUP(A6,metadata!A:F,6,FALSE) -> GalesburgIL | M6: =VLOOKUP(A6,metadata!A:D,4,FALSE) -> 40.990553 | N6: =VLOOKUP(A6,metadata!A:E,5,FALSE) -> -90.399817
A7: QUE001343 | B7: Q. macrocarpa | C7: Q. macrocarpa | D7: 0.99156 | E7: 0 | F7: 0 | G7: 0 | H7: 0 | I7: 0.00844 | J7: Unadmixed | K7: =VLOOKUP(A7,metadata!A:I,9,FALSE) -> IL | L7: =VLOOKUP(A7,metadata!A:F,6,FALSE) -> GalesburgIL | M7: =VLOOKUP(A7,metadata!A:D,4,FALSE) -> 40.989198 | N7: =VLOOKUP(A7,metadata!A:E,5,FALSE) -> -90.398409
A8: QUE001344 | B8: N/A | C8: Q. macrocarpa - Q. alba | D8: 0 | E8: 1 | F8: 0 | G8: 0 | H8: 0 | I8: 0 | J8: F1 | K8: =VLOOKUP(A8,metadata!A:I,9,FALSE) -> IL | L8: =VLOOKUP(A8,metadata!A:F,6,FALSE) -> GalesburgIL | M8: =VLOOKUP(A8,metadata!A:D,4,FALSE) -> 40.988718 | N8: =VLOOKUP(A8,metadata!A:E,5,FALSE) -> -90.398239
A9: QUE001345 | B9: Q. macrocarpa | C9: Q. macrocarpa | D9: 0.99758 | E9: 0 | F9: 0 | G9: 0 | H9: 0 | I9: 0.00242 | J9: Unadmixed | K9: =VLOOKUP(A9,metadata!A:I,9,FALSE) -> IL | L9: =VLOOKUP(A9,metadata!A:F,6,FALSE) -> GalesburgIL | M9: =VLOOKUP(A9,metadata!A:D,4,FALSE) -> 40.988718 | N9: =VLOOKUP(A9,metadata!A:E,5,FALSE) -> -90.398239
A10: QUE001346 | B10: Q. macrocarpa | C10: Q. macrocarpa | D10: 0.99759 | E10: 0 | F10: 0 | G10: 0 | H10: 0 | I10: 0.00241 | J10: Unadmixed | K10: =VLOOKUP(A10,metadata!A:I,9,FALSE) -> IL | L10: =VLOOKUP(A10,metadata!A:F,6,FALSE) -> GalesburgIL | M10: =VLOOKUP(A10,metadata!A:D,4,FALSE) -> 40.988718 | N10: =VLOOKUP(A10,metadata!A:E,5,FALSE) -> -90.398239
A11: QUE001347 | B11: Q. macrocarpa | C11: Q. macrocarpa | D11: 0.99414 | E11: 0 | F11: 0 | G11: 0 | H11: 0 | I11: 0.00586 | J11: Unadmixed | K11: =VLOOKUP(A11,metadata!A:I,9,FALSE) -> IL | L11: =VLOOKUP(A11,metadata!A:F,6,FALSE) -> GalesburgIL | M11: =VLOOKUP(A11,metadata!A:D,4,FALSE) -> 40.987492 | N11: =VLOOKUP(A11,metadata!A:E,5,FALSE) -> -90.393722
A12: QUE001348 | B12: Q. macrocarpa | C12: Q. macrocarpa | D12: 0.98637 | E12: 0 | F12: 0 | G12: 0 | H12: 3e-05 | I12: 0.0136 | J12: Unadmixed | K12: =VLOOKUP(A12,metadata!A:I,9,FALSE) -> IL | L12: =VLOOKUP(A12,metadata!A:F,6,FALSE) -> GalesburgIL | M12: =VLOOKUP(A12,metadata!A:D,4,FALSE) -> 40.987802 | N12: =VLOOKUP(A12,metadata!A:E,5,FALSE) -> -90.393579
A13: QUE001350 | B13: Q. macrocarpa | C13: Q. macrocarpa | D13: 0.99624 | E13: 0 | F13: 0 | G13: 0 | H13: 1e-05 | I13: 0.00375 | J13: Unadmixed | K13: =VLOOKUP(A13,metadata!A:I,9,FALSE) -> IL | L13: =VLOOKUP(A13,metadata!A:F,6,FALSE) -> GalesburgIL | M13: =VLOOKUP(A13,metadata!A:D,4,FALSE) -> 40.987996 | N13: =VLOOKUP(A13,metadata!A:E,5,FALSE) -> -90.393384
... A363: QUE002647 | B363: Q. macrocarpa | C363: Q. macrocarpa | D363: 0.98285 | E363: 0 | F363: 0 | G363: 0 | H363: 2e-05 | I363: 0.01713 | J363: Unadmixed | K363: =VLOOKUP(A363,metadata!A:I,9,FALSE) -> MN | L363: =VLOOKUP(A363,metadata!A:F,6,FALSE) -> AustinMN | M363: =VLOOKUP(A363,metadata!A:D,4,FALSE) -> 43.677 | N363: =VLOOKUP(A363,metadata!A:E,5,FALSE) -> -92.93769

Sheet metadata
A1: Specimen Code | B1: Species | C1: Georeferenced? | D1: Latitude | E1: Longitude | F1: Site | G1: DNA Extraction Code | H1: Country | I1: State/Province | J1: Collector | K1: Collection Number | L1: Collection Date
A2: QUE002637 | B2: Q. macrocarpa | C2: Y | D2: 43.68836 | E2: -92.92859 | F2: AustinMN | G2: JCB-21 | H2: USA | I2: MN | J2: Cathleen Nguyen | K2: MN_FS_110 | L2: 42973
A3: QUE002631 | B3: Q. macrocarpa | C3: Y | D3: 43.68481 | E3: -92.92696 | F3: AustinMN | G3: JCB-23 | H3: USA | I3: MN | J3: Cathleen Nguyen | K3: MN_FS_104 | L3: 42973
A4: QUE002647 | B4: Q. macrocarpa | C4: Y | D4: 43.677 | E4: -92.93769 | F4: AustinMN | G4: JCB-30 | H4: USA | I4: MN | J4: Cathleen Nguyen | K4: MN_JCH_111 | L4: 42971
A5: QUE002613 | B5: Q. macrocarpa | C5: Y | D5: 42.04141 | E5: -93.678679 | F5: AmesIA | G5: JCB-40 | H5: USA | I5: IA | J5: Cathleen Nguyen | K5: IA_101 | L5: 42983
A6: QUE002614 | B6: Q. macrocarpa | C6: Y | D6: 42.049533 | E6: -93.679052 | F6: AmesIA | G6: JCB-41 | H6: USA | I6: IA | J6: Cathleen Nguyen | K6: IA_102 | L6: 42979
A7: QUE002616 | B7: Q. macrocarpa | C7: Y | D7: 42.030898 | E7: -93.632418 | F7: AmesIA | G7: JCB-43 | H7: USA | I7: IA | J7: Cathleen Nguyen | K7: IA_104 | L7: 42979
A8: QUE002617 | B8: Q. macrocarpa | C8: Y | D8: 42.023609 | E8: -93.633087 | F8: AmesIA | G8: JCB-44 | H8: USA | I8: IA | J8: Cathleen Nguyen | K8: IA_105 | L8: 42979
A9: QUE002599 | B9: Q. macrocarpa | C9: Y | D9: 44.226111 | E9: -93.471944 | F9: SakatahLakeMN | G9: JCB-54 | H9: USA | I9: MN | J9: Cathleen Nguyen | K9: MN_SL_112 | L9: 42992
A10: QUE002628 | B10: Q. macrocarpa | C10: N | D10: NA | E10: NA | F10: NA | G10: JCB-58 | H10: USA | I10: MN | J10: Cathleen Nguyen | K10: MN_FS_101 | L10: 42973
A11: QUE002601 | B11: Q. macrocarpa | C11: Y | D11: 44.86798 | E11: -93.03203 | F11: TwinCitiesMN | G11: JCB-68 | H11: USA | I11: MN | J11: Cathleen Nguyen | K11: MN_CDR_102 | L11: 42972
A12: QUE002638 | B12: Q. macrocarpa | C12: Y | D12: 43.677 | E12: -92.93769 | F12: AustinMN | G12: JCB-73 | H12: USA | I12: MN | J12: Cathleen Nguyen | K12: MN_JCH_101 | L12: 42971
A13: QUE002615 | B13: Q. macrocarpa | C13: Y | D13: 42.036203 | E13: -93.639256 | F13: AmesIA | G13: JCB-79 | H13: USA | I13: IA | J13: Cathleen Nguyen | K13: IA_103 | L13: 42979
A14: QUE002595 | B14: Q. macrocarpa | C14: Y | D14: 44.224444 | E14: -93.528333 | F14: SakatahLakeMN | G14: JCB-85 | H14: USA | I14: MN | J14: Cathleen Nguyen | K14: MN_SL_108 | L14: 42992
A15: QUE002634 | B15: Q. macrocarpa | C15: Y | D15: 43.68461 | E15: -92.92134 | F15: AustinMN | G15: JCB-90 | H15: USA | I15: MN | J15: Cathleen Nguyen | K15: MN_FS_107 | L15: 42973
A16: QUE002590 | B16: Q. macrocarpa | C16: Y | D16: 45.38953 | E16: -93.19485 | F16: CedarCreekMN | G16: JCB-91 | H16: USA | I16: MN | J16: Cathleen Nguyen | K16: MN_SL_101 | L16: 42975
A17: QUE002608 | B17: Q. macrocarpa | C17: Y | D17: 45.422222 | E17: -93.188056 | F17: SakatahLakeMN | G17: JCB-97 | H17: USA | I17: MN | J17: Cathleen Nguyen | K17: MN_CDR_109 | L17: 42991
A18: QUE002641 | B18: Q. macrocarpa | C18: Y | D18: 43.68531 | E18: -92.92292 | F18: AustinMN | G18: JCB-99 | H18: USA | I18: MN | J18: Cathleen Nguyen | K18: MN_JCH_105 | L18: 42971
A19: QUE001334 | B19: Q. macrocarpa | C19: Y | D19: 40.990945 | E19: -90.402384 | F19: GalesburgIL | G19: OAK-MOR-000739 | H19: USA | I19: IL | J19: Nick Steichmann | K19: IL-LAKESTOREY-NS2 | L19: 42187
A20: QUE001337 | B20: Q. macrocarpa | C20: Y | D20: 40.990457 | E20: -90.405752 | F20: GalesburgIL | G20: OAK-MOR-000742 | H20: USA | I20: IL | J20: Nick Steichmann | K20: IL-LAKESTOREY-NS5 | L20: 42187
A21: QUE001338 | B21: Q. macrocarpa | C21: Y | D21: 40.990457 | E21: -90.405752 | F21: GalesburgIL | G21: OAK-MOR-000743 | H21: USA | I21: IL | J21: Nick Steichmann | K21: IL-LAKESTOREY-NS6 | L21: 42187
A22: QUE001339 | B22: Q. macrocarpa | C22: Y | D22: 40.990457 | E22: -90.405752 | F22: GalesburgIL | G22: OAK-MOR-000744 | H22: USA | I22: IL | J22: Nick Steichmann | K22: IL-LAKESTOREY-NS7 | L22: 42187
... A106: QUE001982 | B106: Q. macrocarpa | C106: Y | D106: 46.0259 | E106: -91.14288 | F106: RoundLakeWI | G106: OAK-MOR-001265 | H106: USA | I106: WI | J106: Mira Garner; Sara Desmond | K106: WI-MG538 | L106: 42925
A107: QUE002057 | B107: Q. macrocarpa | C107: Y | D107: 38.963586 | E107: -98.58906 | F107: MinookaKS | G107: OAK-MOR-001266 | H107: USA | I107: KS | J107: Ian Pearse | K107: Minooka 2 | L107: NA
A108: QUE002074 | B108: Q. macrocarpa | C108: Y | D108: 39.839311 | E108: -88.367745 | F108: ChickenbristleIL | G108: OAK-MOR-001267 | H108: USA | I108: IL | J108: Ian Pearse | K108: Chickenbristle 3 | L108: NA
A109: QUE002075 | B109: Q. alba | C109: Y | D109: 39.839311 | E109: -88.367745 | F109: ChickenbristleIL | G109: OAK-MOR-001268 | H109: USA | I109: IL | J109: Ian Pearse | K109: Chickenbristle 4 | L109: NA
A110: QUE002081 | B110: Q. macrocarpa | C110: Y | D110: 37.51492 | E110: -89.4445 | F110: ShawneeIL | G110: OAK-MOR-001269 | H110: USA | I110: IL | J110: Mira Garner; Sara Desmond | K110: IL-MG602 | L110: 42941
A111: QUE002082 | B111: Q. macrocarpa | C111: Y | D111: 37.51639 | E111: -89.44535 | F111: ShawneeIL | G111: OAK-MOR-001270 | H111: USA | I111: IL | J111: Mira Garner; Sara Desmond | K111: IL-MG603 | L111: 42941
A112: QUE002085 | B112: Q. macrocarpa | C112: Y | D112: 38.7362 | E112: -86.41257 | F112: SpringMillIN | G112: OAK-MOR-001271 | H112: USA | I112: IN | J112: Mira Garner; Sara Desmond | K112: IN-MG606 | L112: 42942
A113: QUE002091 | B113: Q. alba | C113: Y | D113: 38.73631 | E113: -86.41434 | F113: SpringMillIN | G113: OAK-MOR-001273 | H113: USA | I113: IN | J113: Mira Garner; Sara Desmond | K113: IN-MG612 | L113: 42942
A114: QUE002098 | B114: Q. muehlenbergii | C114: Y | D114: 38.73743 | E114: -86.41263 | F114: SpringMillIN | G114: OAK-MOR-001274 | H114: USA | I114: IN | J114: Mira Garner; Sara Desmond | K114: IN-MG619 | L114: 42942
A115: QUE002105 | B115: Q. macrocarpa | C115: Y | D115: 40.45916 | E115: -85.50807 | F115: TaylorIN | G115: OAK-MOR-001277 | H115: USA | I115: IN | J115: Mira Garner; Sara Desmond | K115: IN-MG626 | L115: 42943
A116: QUE002108 | B116: Q. alba | C116: Y | D116: 40.45911 | E116: -85.50917 | F116: TaylorIN | G116: OAK-MOR-001278 | H116: USA | I116: IN | J116: Mira Garner; Sara Desmond | K116: IN-MG629 | L116: 42943
A117: QUE002121 | B117: Q. alba | C117: Y | D117: 41.65738 | E117: -87.06045 | F117: DunesIN | G117: OAK-MOR-001279 | H117: USA | I117: IN | J117: Mira Garner; Kasey Pham | K117: IN-MG642 | L117: 42957
A118: QUE002129 | B118: Q. macrocarpa | C118: Y | D118: 41.96233 | E118: -73.313005 | F118: LitchfieldCT | G118: OAK-MOR-001280 | H118: USA | I118: CT | J118: Paul Gugger | K118: QUMAC-1028 | L118: 42960
A119: QUE002133 | B119: Q. macrocarpa | C119: Y | D119: 42.166649 | E119: -73.41209 | F119: BerkshireMA | G119: OAK-MOR-001282 | H119: USA | I119: MA | J119: Paul Gugger | K119: QUMAC-1032 | L119: 42960
A120: QUE002138 | B120: Q. alba | C120: Y | D120: 43.604683 | E120: -73.180401 | F120: RutlandVT | G120: OAK-MOR-001284 | H120: USA | I120: VT | J120: Paul Gugger | K120: QUAL-1037 | L120: 42960
A121: QUE002154 | B121: Q. macrocarpa | C121: Y | D121: 44.400681 | E121: -73.23757 | F121: BurlingtonVT | G121: OAK-MOR-001286 | H121: USA | I121: VT | J121: Paul Gugger | K121: QUMAC-1053 | L121: 42961
... A161: QUE002375 | B161: Q. alba | C161: Y | D161: 43.01817 | E161: -90.11679 | F161: DodgevilleWI | G161: OAK-MOR-001347 | H161: USA | I161: WI | J161: Mira Garner | K161: WI-MG712 | L161: 42969
A162: QUE001610 | B162: Q. macrocarpa | C162: Y | D162: 41.81347 | E162: -88.06293 | F162: MortonArbIL | G162: OAK-MOR-001348 | H162: USA | I162: IL | J162: Andrew L. Hipp & Mira Garner | K162: 2017001 | L162: 42867
...
